Workbook

Sheet Respostas ao formulário 1
A1: Carimbo de data/hora | B1: Endereço de e-mail | C1: Qual seu número USP? | D1: Crie um pseudônimo para você? | E1: Qual sua data de nascimento? | F1: Qual sua estatura em metros? | G1: Qual sua massa corporal em quilogramas? | H1: Qual o número do seu calçado? | I1: Sexo (M = masculino ou F = feminino) | J1: Qual o seu tempo de prática no futebol em anos? | K1: Em uma escala entre 1 e 5, qual o seu nível de habilidade no futebol? | L1: Qual time de futebol do Brasil você torce? | M1: Qual seu esporte preferido? | N1: Quantas embaixadinhas você conseguiu fazer?
A2: 44062.92 | C2: 11855641 | D2: Fidelis | E2: 36805 | F2: 1.79 | G2: 72 | H2: 40 | I2: M | J2: 0 | K2: 3 | L2: Nenhum | M2: Fisiculturismo | N2: 5
A3: 44062.92 | C3: 11913405 | D3: GLG | E3: 37176 | F3: 1.66 | G3: 72.1 | H3: 39 | I3: F | J3: 0 | K3: 1 | L3: Nenhum | M3: Vôlei | N3: 2
A4: 44062.925 | C4: 11876742 | D4: Matinho | E4: 31434 | F4: 1.63 | G4: 60 | H4: 38 | I4: F | J4: 0 | K4: 1 | L4: América | M4: Boxe | N4: 1
A5: 44063.392 | C5: 7963755 | D5: phacampos | E5: 33998 | F5: 1.75 | G5: 73 | H5: 40 | I5: M | J5: 2 | K5: 2 | L5: Palmeiras | M5: MMA | N5: 5
A6: 44063.409 | C6: 11782491 | D6: Vi | E6: 36949 | F6: 1.60 | G6: 58 | H6: 37 | I6: F | J6: 0 | K6: 1 | L6: nenhum | M6: vôlei | N6: 3
A7: 44063.425 | C7: 9893257 | D7: Personal das Estrelas | E7: 35948 | F7: 1.85 | G7: 93 | H7: 44 | I7: M | J7: 0 | K7: 1 | L7: Palmeiras | M7: Ginástica | N7: 3
A8: 44064.35 | C8: 11851081 | D8: Gabizão | E8: 37146 | F8: 1.60 | G8: 65 | H8: 36 | I8: F | J8: 7 | K8: 3 | L8: Santos | M8: Futsal | N8: 14
A9: 44063.462 | C9: 11931830 | D9: eu | E9: 37277 | F9: 1.74 | G9: 82 | H9: 42 | I9: M | J9: 0 | K9: 1 | L9: palmeiras | M9: musculação | N9: 3
A10: 44063.467 | C10: 11883243 | D10: Damian | E10: 37432 | F10: 1.83 | G10: 111 | H10: 42 | I10: M | J10: 11 | K10: 3 | L10: Corinthians | M10: Futebol | N10: 36
A11: 44063.477 | C11: 11845970 | D11: Paranauê | E11: 37347 | F11: 1.69 | G11: 85 | H11: 39 | I11: F | J11: 0 | K11: 1 | L11: Corinthians | M11: Capoeira | N11: 2
A12: 44063.482 | C12: 11782592 | D12: Sashi | E12: 36970 | F12: 1.68 | G12: 80 | H12: 39 | I12: F | J12: 0 | K12: 2 | L12: São Paulo | M12: Voleibol | N12: 6
A13: 44063.487 | C13: 11913642 | D13: Marta Camisa 10 | E13: 37075 | F13: 1.75 | G13: 66 | H13: 39 | I13: F | J13: 0 | K13: 1 | L13: São Paulo | M13: Vôlei | N13: 2
A14: 44063.492 | C14: 11847631 | D14: Seca | E14: 37435 | F14: 1.64 | G14: 70 | H14: 38 | I14: F | J14: 0 | K14: 1 | L14: Corinthians | M14: Vôlei | N14: 5
A15: 44063.51 | C15: 11911390 | D15: Matuza | E15: 34649 | F15: 1.75 | G15: 110 | H15: 42 | I15: M | J15: 16 | K15: 4 | L15: Corinthians | M15: Futebol | N15: 30
... A23: 44063.627 | C23: 11908927 | D23: Cadu | E23: 37176 | F23: 1.72 | G23: 68 | H23: 39 | I23: M | J23: 13 | K23: 3 | L23: São Paulo FC e Botafogo SP | M23: Futebol e Futsal | N23: 10
A24: 44063.628 | C24: 11782640 | D24: Molusco | E24: 37484 | F24: 1.75 | G24: 55.7 | H24: 39 | I24: M | J24: 12 | K24: 4 | L24: São Paulo | M24: Futebol | N24: 12
A25: 44063.636 | C25: 11910941 | D25: EHL | E25: 36997 | F25: 1.75 | G25: 67 | H25: 41 | I25: M | J25: 14 | K25: 5 | L25: São paulo | M25: futebol | N25: 15
A26: 44063.639 | C26: 11782334 | D26: Febem | E26: 37337 | F26: 1.89 | G26: 83 | H26: 45 | I26: M | J26: 9 | K26: 4 | L26: Ponte Preta | M26: Basquete | N26: 11
A27: 44063.671 | C27: 11782504 | D27: Comédia | E27: 37442 | F27: 1.65 | G27: 64 | H27: 39 | I27: M | J27: 11 | K27: 5 | L27: São Paulo | M27: Futebol | N27: 22
A28: 44063.672 | C28: 11847781 | D28: NAC | E28: 33272 | F28: 1.65 | G28: 55 | H28: 37 | I28: F | J28: 0 | K28: 1 | L28: Palmeiras | M28: Tênis | N28: 0
A29: 44063.682 | C29: 11916440 | D29: H de habilidoso | E29: 36876 | F29: 1.79 | G29: 68 | H29: 42 | I29: M | J29: 15 | K29: 4 | L29: São Paulo | M29: Futebol | N29: 7
A30: 44063.685 | C30: 11911744 | D30: Fenzza | E30: 36073 | F30: 1.70 | G30: 54 | H30: 36 | I30: F | J30: 0 | K30: 1 | L30: Nenhum | M30: Musculação | N30: 2
A31: 44063.713 | C31: 11782675 | D31: capi | E31: 37352 | F31: 1.77 | G31: 90 | H31: 41 | I31: M | J31: 10 | K31: 2 | L31: São Paulo | M31: Basquete | N31: 5
A32: 44063.716 | C32: 9389511 | D32: TDN | E32: 34544 | F32: 1.71 | G32: 85 | H32: 39 | I32: F | J32: 0 | K32: 1 | L32: Comercial | M32: Handebol | N32: 5
A33: 44063.742 | C33: 11782442 | D33: O de O Breno | E33: 36829 | F33: 1.80 | G33: 80 | H33: 41 | I33: M | J33: 15 | K33: 4 | L33: Palmeiras | M33: Futebol | N33: 13
A34: 44063.746 | C34: 11908545 | D34: GCS | E34: 37375 | F34: 1.75 | G34: 90 | H34: 41 | I34: M | J34: 10 | K34: 3 | L34: São Paulo | M34: futebol | N34: 5
A35: 44063.789 | C35: 10882229 | D35: Eduardo Alexandre | E35: 36213 | F35: 1.64 | G35: 55 | H35: 40 | I35: M | J35: 14 | K35: 3 | L35: Corinthians | M35: futebol | N35: 48
A36: 44063.792 | C36: 11782459 | D36: TRQ | E36: 37251 | F36: 1.80 | G36: 100 | H36: 42 | I36: M | J36: 0 | K36: 2 | L36: NENHUM | M36: Musculação | N36: 3
... A48: 44063.943 | C48: 11846992 | D48: KM | E48: 36950 | F48: 1.60 | G48: 57 | H48: 35 | I48: F | J48: 0 | K48: 5 | L48: Corinthians | M48: Ginástica | N48: 3
A49: 44063.969 | C49: 11368575 | D49: O PAI TA ON | E49: 36550 | F49: 1.67 | G49: 68 | H49: 37 | I49: F | J49: 6 | L49: Fut Rap | M49: Basquete | N49: 9
A50: 44063.981 | C50: 11782661 | D50: Gênio da lâmpada | E50: 37211 | F50: 1.72 | G50: 79 | H50: 42 | I50: M | J50: 1 | L50: Palmeiras | M50: Natação | N50: 5
A51: 44063.992 | C51: 11782567 | D51: Luna | E51: 37420 | F51: 1.61 | G51: 62 | H51: 37 | I51: F | J51: 1 | L51: Palmeiras | M51: Futebol | N51: 10
A52: 44064.068 | C52: 11855679 | D52: Paçoca | E52: 37386 | F52: 1.73 | G52: 72 | H52: 40 | I52: M | J52: 9 | L52: Sport Clube Corinthians Paulista | M52: Futsal | N52: 33
A53: 44064.344 | C53: 11847965 | D53: Foca | E53: 37112 | F53: 1.72 | G53: 59 | H53: 40 | I53: M | J53: 13 | L53: São Paulo | M53: Judô | N53: 8
A54: 44064.347 | C54: 11440238 | D54: Herege | E54: 37296 | F54: 1.81 | G54: 77 | H54: 41 | I54: M | J54: 5 | L54: Palmeiras | M54: Futebol | N54: 13
A55: 44064.355 | C55: 11782380 | D55: pseudo eu | E55: 37452 | F55: 1.65 | G55: 55.8 | H55: 38 | I55: M | J55: 0 | L55: sao paulo | M55: handball | N55: 4
A56: 44064.355 | C56: 11818170 | D56: Militão | E56: 36490 | F56: 1.75 | G56: 64 | H56: 39 | I56: M | J56: 15 | L56: Corinthians | M56: Futebol | N56: 8
A57: 44064.362 | C57: 11782397 | D57: TZ | E57: 37054 | F57: 1.78 | G57: 75 | H57: 41 | I57: M | J57: 4 | L57: São Paulo | M57: Futebol | N57: 6
A58: 44064.371 | C58: 11782546 | D58: Anjinn | E58: 35711 | F58: 1.85 | G58: 115 | H58: 48 | I58: M | J58: 0 | L58: nenhum | M58: Musculação | N58: 3
...

Sheet Página2
A1: 1 | B1: ='Respostas ao formulário 1'!N2 -> 5 | C1: 27 | D1: 0 | E1: N | F1: Numero de elementos | G1: =COUNTA(B:B) -> 59 | L1: Classes | M1: Freq abs | N1: Ponto medio | P1: lim inf | Q1: lim sup
A2: 2 | B2: ='Respostas ao formulário 1'!N3 -> 2 | C2: 3 | D2: 1 | E2: K | F2: Numero de classes (bins) | G2: =SQRT(G1) -> 7.6811457 | H2: =ROUND(G2,0) -> 8 | P2: =-0.049 -> -0.049 | Q2: 6
A3: 3 | B3: ='Respostas ao formulário 1'!N4 -> 1 | C3: 2 | D3: 2 | E3: A | F3: Amplitude | G3: =LARGE(B:B,1)-SMALL(B:B,1) -> 48 | P3: 6 | Q3: 12
A4: 4 | B4: ='Respostas ao formulário 1'!N5 -> 5 | C4: 10 | D4: 2 | E4: H | G4: =G3/G2 -> 6.2490677 | H4: =ROUND(G4,0) -> 6 | I4: =H2*H4 -> 48 | J4: =H2*H4+1 -> 49 | P4: 12 | Q4: 18
A5: 5 | B5: ='Respostas ao formulário 1'!N6 -> 3 | C5: 12 | D5: 2 | P5: 18 | Q5: 24
A6: 6 | B6: ='Respostas ao formulário 1'!N7 -> 3 | C6: 29 | D6: 2 | P6: 24 | Q6: 30
A7: 7 | B7: ='Respostas ao formulário 1'!N8 -> 14 | C7: 41 | D7: 2 | P7: 30 | Q7: 36
A8: 8 | B8: ='Respostas ao formulário 1'!N9 -> 3 | C8: 42 | D8: 2 | P8: 36 | Q8: 42
A9: 9 | B9: ='Respostas ao formulário 1'!N10 -> 36 | C9: 5 | D9: 3 | P9: 42 | Q9: 48
A10: 10 | B10: ='Respostas ao formulário 1'!N11 -> 2 | C10: 6 | D10: 3
A11: 11 | B11: ='Respostas ao formulário 1'!N12 -> 6 | C11: 8 | D11: 3
A12: 12 | B12: ='Respostas ao formulário 1'!N13 -> 2 | C12: 16 | D12: 3
A13: 13 | B13: ='Respostas ao formulário 1'!N14 -> 5 | C13: 35 | D13: 3
A14: 14 | B14: ='Respostas ao formulário 1'!N15 -> 30 | C14: 39 | D14: 3 | M14: {=FREQUENCY(C1:C59,P2:Q9)} -> 0
A15: 15 | B15: ='Respostas ao formulário 1'!N16 -> 14 | C15: 40 | D15: 3 | M15: 6
A16: 16 | B16: ='Respostas ao formulário 1'!N17 -> 3 | C16: 46 | D16: 3 | M16: 0
A17: 17 | B17: ='Respostas ao formulário 1'!N18 -> 4 | C17: 47 | D17: 3 | M17: 6
A18: 18 | B18: ='Respostas ao formulário 1'!N19 -> 17 | C18: 57 | D18: 3 | M18: 0
A19: 19 | B19: ='Respostas ao formulário 1'!N20 -> 10 | C19: 17 | D19: 4 | M19: 6
A20: 20 | B20: ='Respostas ao formulário 1'!N21 -> 5 | C20: 45 | D20: 4 | M20: 0
A21: 21 | B21: ='Respostas ao formulário 1'!N22 -> 9 | C21: 54 | D21: 4 | M21: 6
A22: 22 | B22: ='Respostas ao formulário 1'!N23 -> 10 | C22: 1 | D22: 5 | M22: 0
A23: 23 | B23: ='Respostas ao formulário 1'!N24 -> 12 | C23: 4 | D23: 5 | M23: 6
A24: 24 | B24: ='Respostas ao formulário 1'!N25 -> 15 | C24: 13 | D24: 5 | M24: 0
A25: 25 | B25: ='Respostas ao formulário 1'!N26 -> 11 | C25: 20 | D25: 5 | M25: 6
A26: 26 | B26: ='Respostas ao formulário 1'!N27 -> 22 | C26: 30 | D26: 5 | M26: 0
... A30: 30 | B30: ='Respostas ao formulário 1'!N31 -> 5 | C30: 49 | D30: 5 | M30: 11
A31: 31 | B31: ='Respostas ao formulário 1'!N32 -> 5 | C31: 58 | D31: 5
A32: 32 | B32: ='Respostas ao formulário 1'!N33 -> 13 | C32: 59 | D32: 5
A33: 33 | B33: ='Respostas ao formulário 1'!N34 -> 5 | C33: 11 | D33: 6
A34: 34 | B34: ='Respostas ao formulário 1'!N35 -> 48 | C34: 56 | D34: 6
A35: 35 | B35: ='Respostas ao formulário 1'!N36 -> 3 | C35: 28 | D35: 7
A36: 36 | B36: ='Respostas ao formulário 1'!N37 -> 21 | C36: 52 | D36: 8
A37: 37 | B37: ='Respostas ao formulário 1'!N38 -> 5 | C37: 55 | D37: 8
A38: 38 | B38: ='Respostas ao formulário 1'!N39 -> 17 | C38: 21 | D38: 9
A39: 39 | B39: ='Respostas ao formulário 1'!N40 -> 3 | C39: 44 | D39: 9
A40: 40 | B40: ='Respostas ao formulário 1'!N41 -> 3 | C40: 48 | D40: 9
A41: 41 | B41: ='Respostas ao formulário 1'!N42 -> 2 | C41: 19 | D41: 10
A42: 42 | B42: ='Respostas ao formulário 1'!N43 -> 2 | C42: 22 | D42: 10
... A59: 59 | B59: ='Respostas ao formulário 1'!N60 -> 5 | C59: 34 | D59: 48

Sheet Página3
A1: 27 | B1: ='Respostas ao formulário 1'!N28 -> 0
A2: 3 | B2: ='Respostas ao formulário 1'!N4 -> 1
A3: 2 | B3: ='Respostas ao formulário 1'!N3 -> 2
A4: 10 | B4: ='Respostas ao formulário 1'!N11 -> 2
A5: 12 | B5: ='Respostas ao formulário 1'!N13 -> 2
A6: 29 | B6: ='Respostas ao formulário 1'!N30 -> 2
A7: 41 | B7: ='Respostas ao formulário 1'!N42 -> 2
A8: 42 | B8: ='Respostas ao formulário 1'!N43 -> 2
A9: 5 | B9: ='Respostas ao formulário 1'!N6 -> 3
A10: 6 | B10: ='Respostas ao formulário 1'!N7 -> 3
A11: 8 | B11: ='Respostas ao formulário 1'!N9 -> 3
A12: 16 | B12: ='Respostas ao formulário 1'!N17 -> 3
A13: 35 | B13: ='Respostas ao formulário 1'!N36 -> 3
A14: 39 | B14: ='Respostas ao formulário 1'!N40 -> 3
A15: 40 | B15: ='Respostas ao formulário 1'!N41 -> 3
A16: 46 | B16: ='Respostas ao formulário 1'!N47 -> 3
A17: 47 | B17: ='Respostas ao formulário 1'!N48 -> 3
A18: 57 | B18: ='Respostas ao formulário 1'!N58 -> 3
A19: 17 | B19: ='Respostas ao formulário 1'!N18 -> 4
A20: 45 | B20: ='Respostas ao formulário 1'!N46 -> 4
A21: 54 | B21: ='Respostas ao formulário 1'!N55 -> 4
A22: 1 | B22: ='Respostas ao formulário 1'!N2 -> 5
A23: 4 | B23: ='Respostas ao formulário 1'!N5 -> 5
A24: 13 | B24: ='Respostas ao formulário 1'!N14 -> 5
A25: 20 | B25: ='Respostas ao formulário 1'!N21 -> 5
A26: 30 | B26: ='Respostas ao formulário 1'!N31 -> 5
A27: 31 | B27: ='Respostas ao formulário 1'!N32 -> 5
A28: 33 | B28: ='Respostas ao formulário 1'!N34 -> 5
A29: 37 | B29: ='Respostas ao formulário 1'!N38 -> 5
A30: 49 | B30: ='Respostas ao formulário 1'!N50 -> 5
A31: 58 | B31: ='Respostas ao formulário 1'!N59 -> 5
A32: 59 | B32: ='Respostas ao formulário 1'!N60 -> 5
A33: 11 | B33: ='Respostas ao formulário 1'!N12 -> 6
A34: 56 | B34: ='Respostas ao formulário 1'!N57 -> 6
A35: 28 | B35: ='Respostas ao formulário 1'!N29 -> 7
A36: 52 | B36: ='Respostas ao formulário 1'!N53 -> 8
A37: 55 | B37: ='Respostas ao formulário 1'!N56 -> 8
A38: 21 | B38: ='Respostas ao formulário 1'!N22 -> 9
A39: 44 | B39: ='Respostas ao formulário 1'!N45 -> 9
A40: 48 | B40: ='Respostas ao formulário 1'!N49 -> 9
...
